Workbook
Name cd_planilha: cod_planilha!$A$1

Sheet Armas
B1: Item | E1: Efeito
B2: Nome | C2: Tipo | D2: Nível | E2: Efeito | F2: Qualidade | G2: Bônus
B3: =IFERROR(__xludf.DUMMYFUNCTION("query(IMPORTRANGE(cd_planilha, ""Armas do jogo!B3:H""), ""Where Col7 = TRUE"")"),"Anel estrelado") -> Anel estrelado | C3: =IFERROR(__xludf.DUMMYFUNCTION("""COMPUTED_VALUE"""),"Anel") -> Anel | D3: =IFERROR(__xludf.DUMMYFUNCTION("""COMPUTED_VALUE"""),8.0) -> 8 | E3: =IFERROR(__xludf.DUMMYFUNCTION("""COMPUTED_VALUE"""),"Cone-gélido") -> Cone-gélido | F3: =IFERROR(__xludf.DUMMYFUNCTION("""COMPUTED_VALUE"""),"Épico") -> Épico | G3: =IFERROR(__xludf.DUMMYFUNCTION("""COMPUTED_VALUE"""),"Aumenta a força em 40%") -> Aumenta a força em 40% | H3: =IFERROR(__xludf.DUMMYFUNCTION("""COMPUTED_VALUE"""),TRUE) -> TRUE
B4: =IFERROR(__xludf.DUMMYFUNCTION("""COMPUTED_VALUE"""),"Interesseiro") -> Interesseiro | C4: =IFERROR(__xludf.DUMMYFUNCTION("""COMPUTED_VALUE"""),"Anel") -> Anel | D4: =IFERROR(__xludf.DUMMYFUNCTION("""COMPUTED_VALUE"""),12.0) -> 12 | E4: =IFERROR(__xludf.DUMMYFUNCTION("""COMPUTED_VALUE"""),"Ganancioso 1") -> Ganancioso 1 | F4: =IFERROR(__xludf.DUMMYFUNCTION("""COMPUTED_VALUE"""),"Impecável") -> Impecável | G4: =IFERROR(__xludf.DUMMYFUNCTION("""COMPUTED_VALUE"""),"Encontra mais 50% de ouro durante as missões") -> Encontra mais 50% de ouro durante as missões | H4: =IFERROR(__xludf.DUMMYFUNCTION("""COMPUTED_VALUE"""),TRUE) -> TRUE
B5: =IFERROR(__xludf.DUMMYFUNCTION("""COMPUTED_VALUE"""),"Anel ferradura") -> Anel ferradura | C5: =IFERROR(__xludf.DUMMYFUNCTION("""COMPUTED_VALUE"""),"Anel") -> Anel | D5: =IFERROR(__xludf.DUMMYFUNCTION("""COMPUTED_VALUE"""),20.0) -> 20 | E5: =IFERROR(__xludf.DUMMYFUNCTION("""COMPUTED_VALUE"""),"Líder 1") -> Líder 1 | F5: =IFERROR(__xludf.DUMMYFUNCTION("""COMPUTED_VALUE"""),"Impecável") -> Impecável | G5: =IFERROR(__xludf.DUMMYFUNCTION("""COMPUTED_VALUE"""),"Aumenta o número de companheiros em +1") -> Aumenta o número de companheiros em +1 | H5: =IFERROR(__xludf.DUMMYFUNCTION("""COMPUTED_VALUE"""),TRUE) -> TRUE
B6: =IFERROR(__xludf.DUMMYFUNCTION("""COMPUTED_VALUE"""),"Perseguindo a lua") -> Perseguindo a lua | C6: =IFERROR(__xludf.DUMMYFUNCTION("""COMPUTED_VALUE"""),"Anel") -> Anel | D6: =IFERROR(__xludf.DUMMYFUNCTION("""COMPUTED_VALUE"""),22.0) -> 22 | E6: =IFERROR(__xludf.DUMMYFUNCTION("""COMPUTED_VALUE"""),"Caça-tesouros 1") -> Caça-tesouros 1 | F6: =IFERROR(__xludf.DUMMYFUNCTION("""COMPUTED_VALUE"""),"Impecável") -> Impecável | G6: =IFERROR(__xludf.DUMMYFUNCTION("""COMPUTED_VALUE"""),"Aumenta o número máximo de artefatos e itens de raid encontrados em +2") -> Aumenta o número máximo de artefatos e itens de raid encontrados em +2 | H6: =IFERROR(__xludf.DUMMYFUNCTION("""COMPUTED_VALUE"""),TRUE) -> TRUE
B7: =IFERROR(__xludf.DUMMYFUNCTION("""COMPUTED_VALUE"""),"Anel do Cruzado") -> Anel do Cruzado | C7: =IFERROR(__xludf.DUMMYFUNCTION("""COMPUTED_VALUE"""),"Anel") -> Anel | D7: =IFERROR(__xludf.DUMMYFUNCTION("""COMPUTED_VALUE"""),25.0) -> 25 | E7: =IFERROR(__xludf.DUMMYFUNCTION("""COMPUTED_VALUE"""),"Companheiro de Guerra 1") -> Companheiro de Guerra 1 | F7: =IFERROR(__xludf.DUMMYFUNCTION("""COMPUTED_VALUE"""),"Épico") -> Épico | G7: =IFERROR(__xludf.DUMMYFUNCTION("""COMPUTED_VALUE"""),"Aumenta a taxa de sobrevivência de membros masculinos do grupo em 5%") -> Aumenta a taxa de sobrevivência de membros masculinos do grupo em 5% | H7: =IFERROR(__xludf.DUMMYFUNCTION("""COMPUTED_VALUE"""),TRUE) -> TRUE
B8: =IFERROR(__xludf.DUMMYFUNCTION("""COMPUTED_VALUE"""),"Dragão sinete") -> Dragão sinete | C8: =IFERROR(__xludf.DUMMYFUNCTION("""COMPUTED_VALUE"""),"Anel") -> Anel | D8: =IFERROR(__xludf.DUMMYFUNCTION("""COMPUTED_VALUE"""),26.0) -> 26 | E8: =IFERROR(__xludf.DUMMYFUNCTION("""COMPUTED_VALUE"""),"Resistente 2") -> Resistente 2 | F8: =IFERROR(__xludf.DUMMYFUNCTION("""COMPUTED_VALUE"""),"Impecável") -> Impecável | G8: =IFERROR(__xludf.DUMMYFUNCTION("""COMPUTED_VALUE"""),"Obtém pelo menos 50% de experiência quando ferido e a missão é bem sucedida") -> Obtém pelo menos 50% de experiência quando ferido e a missão é bem sucedida | H8: =IFERROR(__xludf.DUMMYFUNCTION("""COMPUTED_VALUE"""),TRUE) -> TRUE
B9: =IFERROR(__xludf.DUMMYFUNCTION("""COMPUTED_VALUE"""),"Anel de reza") -> Anel de reza | C9: =IFERROR(__xludf.DUMMYFUNCTION("""COMPUTED_VALUE"""),"Anel") -> Anel | D9: =IFERROR(__xludf.DUMMYFUNCTION("""COMPUTED_VALUE"""),27.0) -> 27 | E9: =IFERROR(__xludf.DUMMYFUNCTION("""COMPUTED_VALUE"""),"Reviver 1") -> Reviver 1 | F9: =IFERROR(__xludf.DUMMYFUNCTION("""COMPUTED_VALUE"""),"Impecável") -> Impecável | G9: =IFERROR(__xludf.DUMMYFUNCTION("""COMPUTED_VALUE"""),"Revive um companheiro derrotado 5% das vezes") -> Revive um companheiro derrotado 5% das vezes | H9: =IFERROR(__xludf.DUMMYFUNCTION("""COMPUTED_VALUE"""),TRUE) -> TRUE
B10: =IFERROR(__xludf.DUMMYFUNCTION("""COMPUTED_VALUE"""),"Marca Divina") -> Marca Divina | C10: =IFERROR(__xludf.DUMMYFUNCTION("""COMPUTED_VALUE"""),"Anel") -> Anel | D10: =IFERROR(__xludf.DUMMYFUNCTION("""COMPUTED_VALUE"""),34.0) -> 34 | E10: =IFERROR(__xludf.DUMMYFUNCTION("""COMPUTED_VALUE"""),"Amazona 1") -> Amazona 1 | F10: =IFERROR(__xludf.DUMMYFUNCTION("""COMPUTED_VALUE"""),"Épico") -> Épico | G10: =IFERROR(__xludf.DUMMYFUNCTION("""COMPUTED_VALUE"""),"Aumenta a taxa de sobrevivência de membros femininos do grupo em 5%") -> Aumenta a taxa de sobrevivência de membros femininos do grupo em 5% | H10: =IFERROR(__xludf.DUMMYFUNCTION("""COMPUTED_VALUE"""),TRUE) -> TRUE
B11: =IFERROR(__xludf.DUMMYFUNCTION("""COMPUTED_VALUE"""),"Anel real") -> Anel real | C11: =IFERROR(__xludf.DUMMYFUNCTION("""COMPUTED_VALUE"""),"Anel") -> Anel | D11: =IFERROR(__xludf.DUMMYFUNCTION("""COMPUTED_VALUE"""),36.0) -> 36 | E11: =IFERROR(__xludf.DUMMYFUNCTION("""COMPUTED_VALUE"""),"Líder 1") -> Líder 1 | F11: =IFERROR(__xludf.DUMMYFUNCTION("""COMPUTED_VALUE"""),"Lendário") -> Lendário | G11: =IFERROR(__xludf.DUMMYFUNCTION("""COMPUTED_VALUE"""),"Aumenta o número de companheiros em +1") -> Aumenta o número de companheiros em +1 | H11: =IFERROR(__xludf.DUMMYFUNCTION("""COMPUTED_VALUE"""),TRUE) -> TRUE
B12: =IFERROR(__xludf.DUMMYFUNCTION("""COMPUTED_VALUE"""),"Oráculo") -> Oráculo | C12: =IFERROR(__xludf.DUMMYFUNCTION("""COMPUTED_VALUE"""),"Anel") -> Anel | D12: =IFERROR(__xludf.DUMMYFUNCTION("""COMPUTED_VALUE"""),39.0) -> 39 | E12: =IFERROR(__xludf.DUMMYFUNCTION("""COMPUTED_VALUE"""),"Reviver 1") -> Reviver 1 | F12: =IFERROR(__xludf.DUMMYFUNCTION("""COMPUTED_VALUE"""),"Lendário") -> Lendário | G12: =IFERROR(__xludf.DUMMYFUNCTION("""COMPUTED_VALUE"""),"Revive um companheiro derrotado 5% das vezes") -> Revive um companheiro derrotado 5% das vezes | H12: =IFERROR(__xludf.DUMMYFUNCTION("""COMPUTED_VALUE"""),TRUE) -> TRUE
B13: =IFERROR(__xludf.DUMMYFUNCTION("""COMPUTED_VALUE"""),"Anel Místico") -> Anel Místico | C13: =IFERROR(__xludf.DUMMYFUNCTION("""COMPUTED_VALUE"""),"Anel") -> Anel | D13: =IFERROR(__xludf.DUMMYFUNCTION("""COMPUTED_VALUE"""),40.0) -> 40 | E13: =IFERROR(__xludf.DUMMYFUNCTION("""COMPUTED_VALUE"""),"Curandeiro 2") -> Curandeiro 2 | F13: =IFERROR(__xludf.DUMMYFUNCTION("""COMPUTED_VALUE"""),"Lendário") -> Lendário | G13: =IFERROR(__xludf.DUMMYFUNCTION("""COMPUTED_VALUE"""),"Reduz o tempo de cura de companheiros em 25%") -> Reduz o tempo de cura de companheiros em 25% | H13: =IFERROR(__xludf.DUMMYFUNCTION("""COMPUTED_VALUE"""),TRUE) -> TRUE
B14: =IFERROR(__xludf.DUMMYFUNCTION("""COMPUTED_VALUE"""),"Anel Grotesco") -> Anel Grotesco | C14: =IFERROR(__xludf.DUMMYFUNCTION("""COMPUTED_VALUE"""),"Anel") -> Anel | D14: =IFERROR(__xludf.DUMMYFUNCTION("""COMPUTED_VALUE"""),43.0) -> 43 | E14: =IFERROR(__xludf.DUMMYFUNCTION("""COMPUTED_VALUE"""),"Detectar segredo") -> Detectar segredo | F14: =IFERROR(__xludf.DUMMYFUNCTION("""COMPUTED_VALUE"""),"Épico") -> Épico | G14: =IFERROR(__xludf.DUMMYFUNCTION("""COMPUTED_VALUE"""),"Aumenta o número máximo de artefatos e itens de raid encontrados por cada membro do grupo em +1") -> Aumenta o número máximo de artefatos e itens de raid encontrados por cada membro do grupo em +1 | H14: =IFERROR(__xludf.DUMMYFUNCTION("""COMPUTED_VALUE"""),TRUE) -> TRUE
B15: =IFERROR(__xludf.DUMMYFUNCTION("""COMPUTED_VALUE"""),"Anel Azulado") -> Anel Azulado | C15: =IFERROR(__xludf.DUMMYFUNCTION("""COMPUTED_VALUE"""),"Anel") -> Anel | D15: =IFERROR(__xludf.DUMMYFUNCTION("""COMPUTED_VALUE"""),45.0) -> 45 | E15: =IFERROR(__xludf.DUMMYFUNCTION("""COMPUTED_VALUE"""),"Revide") -> Revide | F15: =IFERROR(__xludf.DUMMYFUNCTION("""COMPUTED_VALUE"""),"Lendário") -> Lendário | G15: =IFERROR(__xludf.DUMMYFUNCTION("""COMPUTED_VALUE"""),"Aumenta a força do equipamento em 20%") -> Aumenta a força do equipamento em 20% | H15: =IFERROR(__xludf.DUMMYFUNCTION("""COMPUTED_VALUE"""),TRUE) -> TRUE
B16: =IFERROR(__xludf.DUMMYFUNCTION("""COMPUTED_VALUE"""),"Anel de casamento") -> Anel de casamento | C16: =IFERROR(__xludf.DUMMYFUNCTION("""COMPUTED_VALUE"""),"Anel") -> Anel | D16: =IFERROR(__xludf.DUMMYFUNCTION("""COMPUTED_VALUE"""),46.0) -> 46 | E16: =IFERROR(__xludf.DUMMYFUNCTION("""COMPUTED_VALUE"""),"Protetor 2") -> Protetor 2 | F16: =IFERROR(__xludf.DUMMYFUNCTION("""COMPUTED_VALUE"""),"Lendário") -> Lendário | G16: =IFERROR(__xludf.DUMMYFUNCTION("""COMPUTED_VALUE"""),"Aumenta a taxa de sobrevivência do grupo em 5%") -> Aumenta a taxa de sobrevivência do grupo em 5% | H16: =IFERROR(__xludf.DUMMYFUNCTION("""COMPUTED_VALUE"""),TRUE) -> TRUE
B17: =IFERROR(__xludf.DUMMYFUNCTION("""COMPUTED_VALUE"""),"Círculo de antimagia") -> Círculo de antimagia | C17: =IFERROR(__xludf.DUMMYFUNCTION("""COMPUTED_VALUE"""),"Anel") -> Anel | D17: =IFERROR(__xludf.DUMMYFUNCTION("""COMPUTED_VALUE"""),50.0) -> 50 | E17: =IFERROR(__xludf.DUMMYFUNCTION("""COMPUTED_VALUE"""),"Armadura do Mago") -> Armadura do Mago | F17: =IFERROR(__xludf.DUMMYFUNCTION("""COMPUTED_VALUE"""),"Épico") -> Épico | G17: =IFERROR(__xludf.DUMMYFUNCTION("""COMPUTED_VALUE"""),"Aumenta a força do equipamento em 25%") -> Aumenta a força do equipamento em 25% | H17: =IFERROR(__xludf.DUMMYFUNCTION("""COMPUTED_VALUE"""),TRUE) -> TRUE
B18: =IFERROR(__xludf.DUMMYFUNCTION("""COMPUTED_VALUE"""),"Anel de Midas") -> Anel de Midas | C18: =IFERROR(__xludf.DUMMYFUNCTION("""COMPUTED_VALUE"""),"Anel") -> Anel | D18: =IFERROR(__xludf.DUMMYFUNCTION("""COMPUTED_VALUE"""),53.0) -> 53 | E18: =IFERROR(__xludf.DUMMYFUNCTION("""COMPUTED_VALUE"""),"Ganancioso 3") -> Ganancioso 3 | F18: =IFERROR(__xludf.DUMMYFUNCTION("""COMPUTED_VALUE"""),"Mítico") -> Mítico | G18: =IFERROR(__xludf.DUMMYFUNCTION("""COMPUTED_VALUE"""),"Encontra mais 200% de ouro durante as missões") -> Encontra mais 200% de ouro durante as missões | H18: =IFERROR(__xludf.DUMMYFUNCTION("""COMPUTED_VALUE"""),TRUE) -> TRUE
B19: =IFERROR(__xludf.DUMMYFUNCTION("""COMPUTED_VALUE"""),"Anel do Conhecimento") -> Anel do Conhecimento | C19: =IFERROR(__xludf.DUMMYFUNCTION("""COMPUTED_VALUE"""),"Anel") -> Anel | D19: =IFERROR(__xludf.DUMMYFUNCTION("""COMPUTED_VALUE"""),58.0) -> 58 | E19: =IFERROR(__xludf.DUMMYFUNCTION("""COMPUTED_VALUE"""),"Encontrar mágica") -> Encontrar mágica | F19: =IFERROR(__xludf.DUMMYFUNCTION("""COMPUTED_VALUE"""),"Mítico") -> Mítico | G19: =IFERROR(__xludf.DUMMYFUNCTION("""COMPUTED_VALUE"""),"Aumenta o número máximo de artefatos e itens de raid encontrados por cada membro do grupo em +2") -> Aumenta o número máximo de artefatos e itens de raid encontrados por cada membro do grupo em +2 | H19: =IFERROR(__xludf.DUMMYFUNCTION("""COMPUTED_VALUE"""),TRUE) -> TRUE
B20: =IFERROR(__xludf.DUMMYFUNCTION("""COMPUTED_VALUE"""),"Poedor do Sol") -> Poedor do Sol | C20: =IFERROR(__xludf.DUMMYFUNCTION("""COMPUTED_VALUE"""),"Arco") -> Arco | D20: =IFERROR(__xludf.DUMMYFUNCTION("""COMPUTED_VALUE"""),6.0) -> 6 | E20: =IFERROR(__xludf.DUMMYFUNCTION("""COMPUTED_VALUE"""),"Velocista 1") -> Velocista 1 | F20: =IFERROR(__xludf.DUMMYFUNCTION("""COMPUTED_VALUE"""),"Lendário") -> Lendário | G20: =IFERROR(__xludf.DUMMYFUNCTION("""COMPUTED_VALUE"""),"Reduz a duração da missão em 10%") -> Reduz a duração da missão em 10% | H20: =IFERROR(__xludf.DUMMYFUNCTION("""COMPUTED_VALUE"""),TRUE) -> TRUE
B21: =IFERROR(__xludf.DUMMYFUNCTION("""COMPUTED_VALUE"""),"Olho de falcão") -> Olho de falcão | C21: =IFERROR(__xludf.DUMMYFUNCTION("""COMPUTED_VALUE"""),"Arco") -> Arco | D21: =IFERROR(__xludf.DUMMYFUNCTION("""COMPUTED_VALUE"""),8.0) -> 8 | E21: =IFERROR(__xludf.DUMMYFUNCTION("""COMPUTED_VALUE"""),"Energético 1") -> Energético 1 | F21: =IFERROR(__xludf.DUMMYFUNCTION("""COMPUTED_VALUE"""),"Impecável") -> Impecável | G21: =IFERROR(__xludf.DUMMYFUNCTION("""COMPUTED_VALUE"""),"Reduz o tempo de espera depois da missão em 50%") -> Reduz o tempo de espera depois da missão em 50% | H21: =IFERROR(__xludf.DUMMYFUNCTION("""COMPUTED_VALUE"""),TRUE) -> TRUE
B22: =IFERROR(__xludf.DUMMYFUNCTION("""COMPUTED_VALUE"""),"Autocarregador") -> Autocarregador | C22: =IFERROR(__xludf.DUMMYFUNCTION("""COMPUTED_VALUE"""),"Arco") -> Arco | D22: =IFERROR(__xludf.DUMMYFUNCTION("""COMPUTED_VALUE"""),18.0) -> 18 | E22: =IFERROR(__xludf.DUMMYFUNCTION("""COMPUTED_VALUE"""),"Sortudo 1") -> Sortudo 1 | F22: =IFERROR(__xludf.DUMMYFUNCTION("""COMPUTED_VALUE"""),"Impecável") -> Impecável | G22: =IFERROR(__xludf.DUMMYFUNCTION("""COMPUTED_VALUE"""),"Evita ferimentos 10% das vezes") -> Evita ferimentos 10% das vezes | H22: =IFERROR(__xludf.DUMMYFUNCTION("""COMPUTED_VALUE"""),TRUE) -> TRUE
B23: =IFERROR(__xludf.DUMMYFUNCTION("""COMPUTED_VALUE"""),"Olho de águia") -> Olho de águia | C23: =IFERROR(__xludf.DUMMYFUNCTION("""COMPUTED_VALUE"""),"Arco") -> Arco | D23: =IFERROR(__xludf.DUMMYFUNCTION("""COMPUTED_VALUE"""),21.0) -> 21 | E23: =IFERROR(__xludf.DUMMYFUNCTION("""COMPUTED_VALUE"""),"Cuidadoso 1") -> Cuidadoso 1 | F23: =IFERROR(__xludf.DUMMYFUNCTION("""COMPUTED_VALUE"""),"Épico") -> Épico | G23: =IFERROR(__xludf.DUMMYFUNCTION("""COMPUTED_VALUE"""),"Diminui a chance de quebra de equipamento em 15% das vezes") -> Diminui a chance de quebra de equipamento em 15% das vezes | H23: =IFERROR(__xludf.DUMMYFUNCTION("""COMPUTED_VALUE"""),TRUE) -> TRUE
B24: =IFERROR(__xludf.DUMMYFUNCTION("""COMPUTED_VALUE"""),"Evelyn") -> Evelyn | C24: =IFERROR(__xludf.DUMMYFUNCTION("""COMPUTED_VALUE"""),"Arco") -> Arco | D24: =IFERROR(__xludf.DUMMYFUNCTION("""COMPUTED_VALUE"""),35.0) -> 35 | E24: =IFERROR(__xludf.DUMMYFUNCTION("""COMPUTED_VALUE"""),"Caça-tesouros 1") -> Caça-tesouros 1 | F24: =IFERROR(__xludf.DUMMYFUNCTION("""COMPUTED_VALUE"""),"Épico") -> Épico | G24: =IFERROR(__xludf.DUMMYFUNCTION("""COMPUTED_VALUE"""),"Aumenta o número máximo de artefatos e itens de raid encontrados em +2") -> Aumenta o número máximo de artefatos e itens de raid encontrados em +2 | H24: =IFERROR(__xludf.DUMMYFUNCTION("""COMPUTED_VALUE"""),TRUE) -> TRUE
B25: =IFERROR(__xludf.DUMMYFUNCTION("""COMPUTED_VALUE"""),"Olho de dragão") -> Olho de dragão | C25: =IFERROR(__xludf.DUMMYFUNCTION("""COMPUTED_VALUE"""),"Arco") -> Arco | D25: =IFERROR(__xludf.DUMMYFUNCTION("""COMPUTED_VALUE"""),37.0) -> 37 | E25: =IFERROR(__xludf.DUMMYFUNCTION("""COMPUTED_VALUE"""),"Fornecedor 1") -> Fornecedor 1 | F25: =IFERROR(__xludf.DUMMYFUNCTION("""COMPUTED_VALUE"""),"Lendário") -> Lendário | G25: =IFERROR(__xludf.DUMMYFUNCTION("""COMPUTED_VALUE"""),"Reduz a chance de companheiros quebrarem o equipamento em 5%") -> Reduz a chance de companheiros quebrarem o equipamento em 5% | H25: =IFERROR(__xludf.DUMMYFUNCTION("""COMPUTED_VALUE"""),TRUE) -> TRUE
B26: =IFERROR(__xludf.DUMMYFUNCTION("""COMPUTED_VALUE"""),"Besta de adamantium") -> Besta de adamantium | C26: =IFERROR(__xludf.DUMMYFUNCTION("""COMPUTED_VALUE"""),"Arco") -> Arco | D26: =IFERROR(__xludf.DUMMYFUNCTION("""COMPUTED_VALUE"""),39.0) -> 39 | E26: =IFERROR(__xludf.DUMMYFUNCTION("""COMPUTED_VALUE"""),"Suporte 1") -> Suporte 1 | F26: =IFERROR(__xludf.DUMMYFUNCTION("""COMPUTED_VALUE"""),"Lendário") -> Lendário | G26: =IFERROR(__xludf.DUMMYFUNCTION("""COMPUTED_VALUE"""),"Impede que o equipamento de um companheiro se quebre 1 vez") -> Impede que o equipamento de um companheiro se quebre 1 vez | H26: =IFERROR(__xludf.DUMMYFUNCTION("""COMPUTED_VALUE"""),TRUE) -> TRUE
B27: =IFERROR(__xludf.DUMMYFUNCTION("""COMPUTED_VALUE"""),"Besta de repetição") -> Besta de repetição | C27: =IFERROR(__xludf.DUMMYFUNCTION("""COMPUTED_VALUE"""),"Arco") -> Arco | D27: =IFERROR(__xludf.DUMMYFUNCTION("""COMPUTED_VALUE"""),42.0) -> 42 | E27: =IFERROR(__xludf.DUMMYFUNCTION("""COMPUTED_VALUE"""),"Berserker") -> Berserker | F27: =IFERROR(__xludf.DUMMYFUNCTION("""COMPUTED_VALUE"""),"Mítico") -> Mítico | G27: =IFERROR(__xludf.DUMMYFUNCTION("""COMPUTED_VALUE"""),"Aumenta a força em 35%") -> Aumenta a força em 35% | H27: =IFERROR(__xludf.DUMMYFUNCTION("""COMPUTED_VALUE"""),TRUE) -> TRUE
B28: =IFERROR(__xludf.DUMMYFUNCTION("""COMPUTED_VALUE"""),"Arco dos elfos") -> Arco dos elfos | C28: =IFERROR(__xludf.DUMMYFUNCTION("""COMPUTED_VALUE"""),"Arco") -> Arco | D28: =IFERROR(__xludf.DUMMYFUNCTION("""COMPUTED_VALUE"""),43.0) -> 43 | E28: =IFERROR(__xludf.DUMMYFUNCTION("""COMPUTED_VALUE"""),"Detectar segredo") -> Detectar segredo | F28: =IFERROR(__xludf.DUMMYFUNCTION("""COMPUTED_VALUE"""),"Mítico") -> Mítico | G28: =IFERROR(__xludf.DUMMYFUNCTION("""COMPUTED_VALUE"""),"Aumenta o número máximo de artefatos e itens de raid encontrados por cada membro do grupo em +1") -> Aumenta o número máximo de artefatos e itens de raid encontrados por cada membro do grupo em +1 | H28: =IFERROR(__xludf.DUMMYFUNCTION("""COMPUTED_VALUE"""),TRUE) -> TRUE
B29: =IFERROR(__xludf.DUMMYFUNCTION("""COMPUTED_VALUE"""),"Arco do deus do sol") -> Arco do deus do sol | C29: =IFERROR(__xludf.DUMMYFUNCTION("""COMPUTED_VALUE"""),"Arco") -> Arco | D29: =IFERROR(__xludf.DUMMYFUNCTION("""COMPUTED_VALUE"""),45.0) -> 45 | E29: =IFERROR(__xludf.DUMMYFUNCTION("""COMPUTED_VALUE"""),"Sábio 1") -> Sábio 1 | F29: =IFERROR(__xludf.DUMMYFUNCTION("""COMPUTED_VALUE"""),"Mítico") -> Mítico | G29: =IFERROR(__xludf.DUMMYFUNCTION("""COMPUTED_VALUE"""),"25% de bônus de experiência") -> 25% de bônus de experiência | H29: =IFERROR(__xludf.DUMMYFUNCTION("""COMPUTED_VALUE"""),TRUE) -> TRUE
B30: =IFERROR(__xludf.DUMMYFUNCTION("""COMPUTED_VALUE"""),"Fura-Vento") -> Fura-Vento | C30: =IFERROR(__xludf.DUMMYFUNCTION("""COMPUTED_VALUE"""),"Arco") -> Arco | D30: =IFERROR(__xludf.DUMMYFUNCTION("""COMPUTED_VALUE"""),48.0) -> 48 | E30: =IFERROR(__xludf.DUMMYFUNCTION("""COMPUTED_VALUE"""),"Gangster 2") -> Gangster 2 | F30: =IFERROR(__xludf.DUMMYFUNCTION("""COMPUTED_VALUE"""),"Lendário") -> Lendário | G30: =IFERROR(__xludf.DUMMYFUNCTION("""COMPUTED_VALUE"""),"Aumenta a força do equipamento em 25%") -> Aumenta a força do equipamento em 25% | H30: =IFERROR(__xludf.DUMMYFUNCTION("""COMPUTED_VALUE"""),TRUE) -> TRUE
B31: =IFERROR(__xludf.DUMMYFUNCTION("""COMPUTED_VALUE"""),"Assassino licantropo") -> Assassino licantropo | C31: =IFERROR(__xludf.DUMMYFUNCTION("""COMPUTED_VALUE"""),"Arco") -> Arco | D31: =IFERROR(__xludf.DUMMYFUNCTION("""COMPUTED_VALUE"""),50.0) -> 50 | E31: =IFERROR(__xludf.DUMMYFUNCTION("""COMPUTED_VALUE"""),"Detectar segredo") -> Detectar segredo | F31: =IFERROR(__xludf.DUMMYFUNCTION("""COMPUTED_VALUE"""),"Mítico") -> Mítico | G31: =IFERROR(__xludf.DUMMYFUNCTION("""COMPUTED_VALUE"""),"Aumenta o número máximo de artefatos e itens de raid encontrados por cada membro do grupo em +1") -> Aumenta o número máximo de artefatos e itens de raid encontrados por cada membro do grupo em +1 | H31: =IFERROR(__xludf.DUMMYFUNCTION("""COMPUTED_VALUE"""),TRUE) -> TRUE
B32: =IFERROR(__xludf.DUMMYFUNCTION("""COMPUTED_VALUE"""),"Arco de Artemisa") -> Arco de Artemisa | C32: =IFERROR(__xludf.DUMMYFUNCTION("""COMPUTED_VALUE"""),"Arco") -> Arco | D32: =IFERROR(__xludf.DUMMYFUNCTION("""COMPUTED_VALUE"""),54.0) -> 54 | E32: =IFERROR(__xludf.DUMMYFUNCTION("""COMPUTED_VALUE"""),"Engenhoso 2") -> Engenhoso 2 | F32: =IFERROR(__xludf.DUMMYFUNCTION("""COMPUTED_VALUE"""),"Mítico") -> Mítico | G32: =IFERROR(__xludf.DUMMYFUNCTION("""COMPUTED_VALUE"""),"Impede que 2 peças de equipamento se quebre durante a missão") -> Impede que 2 peças de equipamento se quebre durante a missão | H32: =IFERROR(__xludf.DUMMYFUNCTION("""COMPUTED_VALUE"""),TRUE) -> TRUE
B33: =IFERROR(__xludf.DUMMYFUNCTION("""COMPUTED_VALUE"""),"Meteoros") -> Meteoros | C33: =IFERROR(__xludf.DUMMYFUNCTION("""COMPUTED_VALUE"""),"Arco") -> Arco | D33: =IFERROR(__xludf.DUMMYFUNCTION("""COMPUTED_VALUE"""),55.0) -> 55 | E33: =IFERROR(__xludf.DUMMYFUNCTION("""COMPUTED_VALUE"""),"Caça-tesouros 3") -> Caça-tesouros 3 | F33: =IFERROR(__xludf.DUMMYFUNCTION("""COMPUTED_VALUE"""),"Épico") -> Épico | G33: =IFERROR(__xludf.DUMMYFUNCTION("""COMPUTED_VALUE"""),"Aumenta o número máximo de artefatos e itens de raid encontrados em +6") -> Aumenta o número máximo de artefatos e itens de raid encontrados em +6 | H33: =IFERROR(__xludf.DUMMYFUNCTION("""COMPUTED_VALUE"""),TRUE) -> TRUE
B34: =IFERROR(__xludf.DUMMYFUNCTION("""COMPUTED_VALUE"""),"Fúria da Natureza") -> Fúria da Natureza | C34: =IFERROR(__xludf.DUMMYFUNCTION("""COMPUTED_VALUE"""),"Arco") -> Arco | D34: =IFERROR(__xludf.DUMMYFUNCTION("""COMPUTED_VALUE"""),56.0) -> 56 | E34: =IFERROR(__xludf.DUMMYFUNCTION("""COMPUTED_VALUE"""),"Energético 3") -> Energético 3 | F34: =IFERROR(__xludf.DUMMYFUNCTION("""COMPUTED_VALUE"""),"Épico") -> Épico | G34: =IFERROR(__xludf.DUMMYFUNCTION("""COMPUTED_VALUE"""),"Reduz o tempo de espera depois da missão em 100%") -> Reduz o tempo de espera depois da missão em 100% | H34: =IFERROR(__xludf.DUMMYFUNCTION("""COMPUTED_VALUE"""),TRUE) -> TRUE
B35: =IFERROR(__xludf.DUMMYFUNCTION("""COMPUTED_VALUE"""),"Armadura Lunar") -> Armadura Lunar | C35: =IFERROR(__xludf.DUMMYFUNCTION("""COMPUTED_VALUE"""),"Armadura") -> Armadura | D35: =IFERROR(__xludf.DUMMYFUNCTION("""COMPUTED_VALUE"""),10.0) -> 10 | E35: =IFERROR(__xludf.DUMMYFUNCTION("""COMPUTED_VALUE"""),"Caça-tesouros 1") -> Caça-tesouros 1 | F35: =IFERROR(__xludf.DUMMYFUNCTION("""COMPUTED_VALUE"""),"Impecável") -> Impecável | G35: =IFERROR(__xludf.DUMMYFUNCTION("""COMPUTED_VALUE"""),"Aumenta o número máximo de artefatos e itens de raid encontrados em +2") -> Aumenta o número máximo de artefatos e itens de raid encontrados em +2 | H35: =IFERROR(__xludf.DUMMYFUNCTION("""COMPUTED_VALUE"""),TRUE) -> TRUE
B36: =IFERROR(__xludf.DUMMYFUNCTION("""COMPUTED_VALUE"""),"Armadura Nobre") -> Armadura Nobre | C36: =IFERROR(__xludf.DUMMYFUNCTION("""COMPUTED_VALUE"""),"Armadura") -> Armadura | D36: =IFERROR(__xludf.DUMMYFUNCTION("""COMPUTED_VALUE"""),18.0) -> 18 | E36: =IFERROR(__xludf.DUMMYFUNCTION("""COMPUTED_VALUE"""),"Suporte 1") -> Suporte 1 | F36: =IFERROR(__xludf.DUMMYFUNCTION("""COMPUTED_VALUE"""),"Impecável") -> Impecável | G36: =IFERROR(__xludf.DUMMYFUNCTION("""COMPUTED_VALUE"""),"Impede que o equipamento de um companheiro se quebre 1 vez") -> Impede que o equipamento de um companheiro se quebre 1 vez | H36: =IFERROR(__xludf.DUMMYFUNCTION("""COMPUTED_VALUE"""),TRUE) -> TRUE
B37: =IFERROR(__xludf.DUMMYFUNCTION("""COMPUTED_VALUE"""),"Correio de Honra") -> Correio de Honra | C37: =IFERROR(__xludf.DUMMYFUNCTION("""COMPUTED_VALUE"""),"Armadura") -> Armadura | D37: =IFERROR(__xludf.DUMMYFUNCTION("""COMPUTED_VALUE"""),24.0) -> 24 | E37: =IFERROR(__xludf.DUMMYFUNCTION("""COMPUTED_VALUE"""),"Reviver 2") -> Reviver 2 | F37: =IFERROR(__xludf.DUMMYFUNCTION("""COMPUTED_VALUE"""),"Lendário") -> Lendário | G37: =IFERROR(__xludf.DUMMYFUNCTION("""COMPUTED_VALUE"""),"Revive um companheiro derrotado 10% das vezes") -> Revive um companheiro derrotado 10% das vezes | H37: =IFERROR(__xludf.DUMMYFUNCTION("""COMPUTED_VALUE"""),TRUE) -> TRUE
B38: =IFERROR(__xludf.DUMMYFUNCTION("""COMPUTED_VALUE"""),"Armadura do Caos") -> Armadura do Caos | C38: =IFERROR(__xludf.DUMMYFUNCTION("""COMPUTED_VALUE"""),"Armadura") -> Armadura | D38: =IFERROR(__xludf.DUMMYFUNCTION("""COMPUTED_VALUE"""),25.0) -> 25 | E38: =IFERROR(__xludf.DUMMYFUNCTION("""COMPUTED_VALUE"""),"Resistente 1") -> Resistente 1 | F38: =IFERROR(__xludf.DUMMYFUNCTION("""COMPUTED_VALUE"""),"Épico") -> Épico | G38: =IFERROR(__xludf.DUMMYFUNCTION("""COMPUTED_VALUE"""),"Obtém pelo menos 25% de experiência quando ferido e a missão é bem sucedida") -> Obtém pelo menos 25% de experiência quando ferido e a missão é bem sucedida | H38: =IFERROR(__xludf.DUMMYFUNCTION("""COMPUTED_VALUE"""),TRUE) -> TRUE
B39: =IFERROR(__xludf.DUMMYFUNCTION("""COMPUTED_VALUE"""),"Malha Eldritch") -> Malha Eldritch | C39: =IFERROR(__xludf.DUMMYFUNCTION("""COMPUTED_VALUE"""),"Armadura") -> Armadura | D39: =IFERROR(__xludf.DUMMYFUNCTION("""COMPUTED_VALUE"""),35.0) -> 35 | E39: =IFERROR(__xludf.DUMMYFUNCTION("""COMPUTED_VALUE"""),"Sortudo 1") -> Sortudo 1 | F39: =IFERROR(__xludf.DUMMYFUNCTION("""COMPUTED_VALUE"""),"Épico") -> Épico | G39: =IFERROR(__xludf.DUMMYFUNCTION("""COMPUTED_VALUE"""),"Evita ferimentos 10% das vezes") -> Evita ferimentos 10% das vezes | H39: =IFERROR(__xludf.DUMMYFUNCTION("""COMPUTED_VALUE"""),TRUE) -> TRUE
B40: =IFERROR(__xludf.DUMMYFUNCTION("""COMPUTED_VALUE"""),"Fortaleza de Gaia") -> Fortaleza de Gaia | C40: =IFERROR(__xludf.DUMMYFUNCTION("""COMPUTED_VALUE"""),"Armadura") -> Armadura | D40: =IFERROR(__xludf.DUMMYFUNCTION("""COMPUTED_VALUE"""),38.0) -> 38 | E40: =IFERROR(__xludf.DUMMYFUNCTION("""COMPUTED_VALUE"""),"Comandante 1") -> Comandante 1 | F40: =IFERROR(__xludf.DUMMYFUNCTION("""COMPUTED_VALUE"""),"Lendário") -> Lendário | G40: =IFERROR(__xludf.DUMMYFUNCTION("""COMPUTED_VALUE"""),"Aumenta a força dos guerreiros do grupo em 15%") -> Aumenta a força dos guerreiros do grupo em 15% | H40: =IFERROR(__xludf.DUMMYFUNCTION("""COMPUTED_VALUE"""),TRUE) -> TRUE
...

Sheet Personagem
B1: Albert | C1: Alicia | D1: Azula | E1: Charles | F1: Clovis | G1: Darthos | H1: Edward | I1: Fiora | J1: Francesca | K1: Garreth | L1: Gauvin | M1: Irene | N1: Karal | O1: Kuro Shobi | P1: Kurul | Q1: Lancaster | R1: Lorelei | S1: Louca | T1: Melina | U1: Mila | V1: Minh | W1: Mojian | X1: Nya | Y1: Odette | Z1: Oneira | AA1: Palash | AB1: Theor | AC1: Yue
A2: Arma | B2: Arco | C2: Espada | D2: Cajado | E2: Cajado | F2: Espada | G2: Espada | H2: Espada | I2: Cajado | J2: Cajado | K2: Arco | L2: Espada | M2: Espada | N2: Lança | O2: Arco | P2: Lança | Q2: Espada | R2: Faca | S2: Martelo | T2: Arco | U2: Arco | V2: Arco | W2: Arco | X2: Cajado | Y2: Arco | Z2: Arco | AA2: Arco | AB2: Espada | AC2: Arco
B3: Cajado | C3: Lança | D3: Faca | E3: Arco | F3: Lança | G3: Faca | H3: Lança | I3: Espada | J3: Espada | K3: Faca | L3: Lança | M3: Faca | N3: Machado | O3: Espada | P3: Machado | Q3: Lança | R3: Pistola | S3: Pistola | T3: Cajado | U3: Faca | V3: Cajado | W3: Cajado | X3: Faca | Y3: Espada | Z3: Cajado | AA3: Machado | AB3: Lança | AC3: Espada
B4: Faca | C4: Machado | D4: Lança | F4: Machado | G4: Pistola | H4: Machado | I4: Lança | J4: Lança | K4: Pistola | L4: Machado | M4: Pistola | N4: Martelo | O4: Faca | P4: Martelo | Q4: Machado | T4: Faca | U4: Martelo | V4: Martelo | W4: Pistola | X4: Lança | Y4: Faca | Z4: Faca | AA4: Pistola | AB4: Machado | AC4: Lança
C5: Martelo | F5: Martelo | H5: Martelo | I5: Martelo | J5: Pistola | L5: Martelo | O5: Pistola | Q5: Martelo | Y5: Pistola | AB5: Martelo
A6: Peito | B6: Túnica | C6: Armadura | D6: Túnica | E6: Túnica | F6: Armadura | G6: Veste | H6: Armadura | I6: Armadura | J6: Armadura | K6: Veste | L6: Armadura | M6: Veste | N6: Armadura | O6: Túnica | P6: Armadura | Q6: Armadura | R6: Túnica | S6: Veste | T6: Túnica | U6: Veste | V6: Túnica | W6: Armadura | X6: Túnica | Y6: Túnica | Z6: Túnica | AA6: Veste | AB6: Armadura | AC6: Armadura
B7: Veste | E7: Veste | H7: Túnica | I7: Túnica | J7: Túnica | N7: Veste | O7: Veste | P7: Veste | R7: Veste | W7: Túnica | Y7: Veste | AB7: Veste | AC7: Veste
A8: Cabeça | B8: Chapéu | C8: Elmo | D8: Chapéu | E8: Chapéu | F8: Elmo | G8: Chapéu | H8: Elmo | I8: Elmo | J8: Elmo | K8: Chapéu | L8: Elmo | M8: Chapéu | N8: Elmo | O8: Chapéu | P8: Elmo | Q8: Elmo | R8: Chapéu | S8: Chapéu | T8: Chapéu | U8: Chapéu | V8: Chapéu | W8: Elmo | X8: Chapéu | Y8: Chapéu | Z8: Chapéu | AA8: Chapéu | AB8: Elmo | AC8: Chapéu
G9: Elmo | AC9: Elmo
A10: Mãos | B10: Luvas | C10: Manopla | D10: Luvas | E10: Luvas | F10: Manopla | G10: Luvas | H10: Manopla | I10: Manopla | J10: Manopla | K10: Luvas | L10: Manopla | M10: Luvas | N10: Manopla | O10: Luvas | P10: Manopla | Q10: Manopla | R10: Luvas | S10: Manopla | T10: Luvas | U10: Luvas | V10: Luvas | W10: Manopla | X10: Luvas | Y10: Luvas | Z10: Luvas | AA10: Luvas | AB10: Manopla | AC10: Luvas
AC11: Manopla
A12: Pés | B12: Sapatos | C12: Botas | D12: Sapatos | E12: Sapatos | F12: Botas | G12: Botas | H12: Botas | I12: Botas | J12: Botas | K12: Sapatos | L12: Botas | M12: Botas | N12: Botas | O12: Sapatos | P12: Botas | Q12: Botas | R12: Sapatos | S12: Botas | T12: Sapatos | U12: Sapatos | V12: Sapatos | W12: Botas | X12: Sapatos | Y12: Sapatos | Z12: Sapatos | AA12: Sapatos | AB12: Botas | AC12: Botas
S13: Sapatos | AC13: Sapatos
A14: Acessório 1 | B14: Instrumento | C14: Escudo | D14: Anel | E14: Instrumento | F14: Escudo | G14: Anel | H14: Escudo | I14: Anel | J14: Instrumento | K14: Anel | L14: Escudo | M14: Anel | N14: Escudo | O14: Anel | P14: Escudo | Q14: Escudo | R14: Anel | S14: Anel | T14: Anel | U14: Anel | V14: Instrumento | W14: Pingente | X14: Anel | Y14: Anel | Z14: Anel | AA14: Anel | AB14: Escudo | AC14: Pingente
B15: Pingente | C15: Instrumento | D15: Instrumento | G15: Escudo | I15: Escudo | K15: Pingente | L15: Pingente | M15: Escudo | N15: Pingente | O15: Instrumento | P15: Pingente | S15: Escudo | T15: Pingente | U15: Pingente | V15: Pingente | X15: Instrumento | Y15: Pingente | Z15: Instrumento | AA15: Instrumento
D16: Pingente | S16: Pingente | Z16: Pingente
A17: Acessório 2 | B17: Pergaminho | C17: Erva | D17: Erva | E17: Pergaminho | F17: Erva | G17: Erva | H17: Pergaminho | I17: Poção | J17: Pergaminho | K17: Erva | L17: Erva | M17: Poção | N17: Poção | O17: Projétil | P17: Erva | Q17: Erva | R17: Projétil | S17: Erva | T17: Erva | U17: Erva | V17: Pergaminho | W17: Pergaminho | X17: Erva | Y17: Projétil | Z17: Pergaminho | AA17: Erva | AB17: Erva | AC17: Erva
B18: Poção | C18: Projétil | D18: Pergaminho | F18: Poção | G18: Projétil | H18: Poção | J18: Poção | K18: Projétil | L18: Poção | M18: Projétil | N18: Projétil | Q18: Poção | S18: Projétil | T18: Pergaminho | U18: Projétil | V18: Poção | W18: Poção | X18: Pergaminho | Z18: Poção | AA18: Projétil | AC18: Pergaminho
A20: Consultar na tabela dinâmica os equipamentos que o personagem usa

Sheet cod_planilha
A1: "15YC3Wi7qFmdVjHeW_UCnbsoqaugkIEVJhDMDhRjct1c"

Sheet Armas do jogo
B1: Item | E1: Efeito
B2: Nome | C2: Tipo | D2: Nível | E2: Efeito | F2: Qualidade | G2: Bônus | H2: Tem? | I2: Onde conseguir
B3: Anel estrelado | C3: Anel | D3: 8 | E3: Cone-gélido | F3: Épico | G3: =IF(or(E3="Bola de fogo", E3="Cortar", E3="Esmagar"), "Aumenta a força em 25%", if(E3="Pele de pedra", "Aumenta a força em 30%", if(E3="Berserker", "Aumenta a força em 35%", if(E3="Cone-gélido", "Aumenta a força em 40%", if(E3="Raio elétrico", "Aumenta a força em 50%", if(E3="Emboscada", "Aumenta a força 25% das vezes", if(E3="Defesa", "Aumenta a defesa do equipamento em 10%", if(E3="Passo das Sombras", "Evita ferimentos 15% das vezes", if(E3="Detectar segredo", "Aumenta o número máximo de artefatos e itens de raid encontrados por cada membro do grupo em +1", if(E3="Encontrar mágica", "Aumenta o número máximo de artefatos e itens de raid encontrados por cada membro do grupo em +2", if(E3="Aura de proteção", "Aumenta a taxa de sobrevivência do grupo em 8%", if(E3="Revide", "Aumenta a força do equipamento em 20%", if(E3="Mestre das armas", "Aumenta a força do equipamento em 75%", if(E3="Arquimago 1", "Aumenta a força dos feiticeiros do grupo em 10%", if(E3="Arquimago 2", "Aumenta a força dos feiticeiros do grupo em 20%", if(E3="Arquimago 3", "Aumenta a força dos feiticeiros do grupo em 30%", if(E3="Energético 1", "Reduz o tempo de espera depois da missão em 50%", if(E3="Energético 2", "Reduz o tempo de espera depois da missão em 75%", if(E3="Energético 3", "Reduz o tempo de espera depois da missão em 100%", if(E3="Cuidadoso 1", "Diminui a chance de quebra de equipamento em 15% das vezes", if(E3="Cuidadoso 2", "Diminui a chance de quebra de equipamento em 30% das vezes", if(E3="Cuidadoso 3", "Diminui a chance de quebra de equipamento em 50% das vezes", if(E3="Ganancioso 1", "Encontra mais 50% de ouro durante as missões", if(E3="Ganancioso 2", "Encontra mais 100% de ouro durante as missões", if(E3="Ganancioso 3", "Encontra mais 200% de ouro durante as missões", if(E3="Curandeiro 1", "Reduz o tempo de cura de companheiros em 10%", if(E3="Curandeiro 2", "Reduz o tempo de cura de companheiros em 25%", if(E3="Curandeiro 3", "Reduz o tempo de cura de companheiros em 50%", if(E3="Sortudo 1", "Evita ferimentos 10% das vezes", if(E3="Sortudo 2", "Evita ferimentos 20% das vezes", if(E3="Sortudo 3", "Evita ferimentos 30% das vezes", if(E3="Protetor 1", "Aumenta a taxa de sobrevivência do grupo em 2%", if(E3="Protetor 2", "Aumenta a taxa de sobrevivência do grupo em 5%", if(E3="Protetor 3", "Aumenta a taxa de sobrevivência do grupo em 10%", if(E3="Resistente 1", "Obtém pelo menos 25% de experiência quando ferido e a missão é bem sucedida", if(E3="Resistente 2", "Obtém pelo menos 50% de experiência quando ferido e a missão é bem sucedida", if(E3="Resistente 3", "Obtém pelo menos 100% de experiência quando ferido e a missão é bem sucedida", if(E3="Engenhoso 1", "Impede que 1 peça de equipamento se quebre durante a missão", if(E3="Engenhoso 2", "Impede que 2 peças de equipamento se quebre durante a missão", if(E3="Engenhoso 3", "Impede que 3 peças de equipamento se quebre durante a missão", if(E3="Reviver 1", "Revive um companheiro derrotado 5% das vezes", if(E3="Reviver 2", "Revive um companheiro derrotado 10% das vezes", if(E3="Reviver 3", "Revive um companheiro derrotado 15% das vezes", if(E3="Catador 1", "Aumenta o número mínimo de itens e artefatos encontrados em +1", if(E3="Catador 2", "Aumenta o número mínimo de itens e artefatos encontrados em +2", if(E3="Catador 3", "Aumenta o número mínimo de itens e artefatos encontrados em +3", if(E3="Fornecedor 1", "Reduz a chance de companheiros quebrarem o equipamento em 5%", if(E3="Fornecedor 2", "Reduz a chance de companheiros quebrarem o equipamento em 10%", if(E3="Fornecedor 3", "Reduz a chance de companheiros quebrarem o equipamento em 15%", if(E3="Suporte 1", "Impede que o equipamento de um companheiro se quebre 1 vez", if(E3="Suporte 2", "Impede que o equipamento de um companheiro se quebre 2 vezes", if(E3="Suporte 3", "Impede que o equipamento de um companheiro se quebre 3 vezes", if(E3="Caça-tesouros 1", "Aumenta o número máximo de artefatos e itens de raid encontrados em +2", if(E3="Caça-tesouros 2", "Aumenta o número máximo de artefatos e itens de raid encontrados em +4", if(E3="Caça-tesouros 3", "Aumenta o número máximo de artefatos e itens de raid encontrados em +6", if(E3="Sábio 1", "25% de bônus de experiência", if(E3="Sábio 2", "50% de bônus de experiência", if(E3="Sábio 3", "100% de bônus de experiência", if(E3="Amazona 1", "Aumenta a taxa de sobrevivência de membros femininos do grupo em 5%", if(E3="Amazona 2", "Aumenta a taxa de sobrevivência de membros femininos do grupo em 10%", if(E3="Amazona 3", "Aumenta a taxa de sobrevivência de membros femininos do grupo em 25%", if(E3="Companheiro de Guerra 1", "Aumenta a taxa de sobrevivência de membros masculinos do grupo em 5%", if(E3="Companheiro de Guerra 2", "Aumenta a taxa de sobrevivência de membros masculinos do grupo em 10%", if(E3="Companheiro de Guerra 3", "Aumenta a taxa de sobrevivência de membros masculinos do grupo em 25%", if(E3="Comandante 1", "Aumenta a força dos guerreiros do grupo em 15%", if(E3="Comandante 2", "Aumenta a força dos guerreiros do grupo em 25%", if(E3="Comandante 3", "Aumenta a força dos guerreiros do grupo em 50%", if(E3="Gangster 1", "Aumenta a força do equipamento em 10%", if(or(E3="Gangster 2", E3="Armadura do Mago"), "Aumenta a força do equipamento em 25%", if(E3="Gangster 3", "Aumenta a força do equipamento em 50%", if(E3="Líder 1", "Aumenta o número de companheiros em +1", if(E3="Líder 2", "Aumenta o número de companheiros em +2", if(E3="Líder 3", "Aumenta o número de companheiros em +3", if(E3="Velocista 1", "Reduz a duração da missão em 10%", if(E3="Velocista 2", "Reduz a duração da missão em 25%", if(E3="Velocista 3", "Reduz a duração da missão em 50%", )))))))))))))))))))))))))))))))))))))))))))))))))))))))))))))))))))))))))))) -> Aumenta a força em 40% | H3: TRUE | I3: Superhero Pack
B4: Interesseiro | C4: Anel | D4: 12 | E4: Ganancioso 1 | F4: Impecável | G4: =IF(or(E4="Bola de fogo", E4="Cortar", E4="Esmagar"), "Aumenta a força em 25%", if(E4="Pele de pedra", "Aumenta a força em 30%", if(E4="Berserker", "Aumenta a força em 35%", if(E4="Cone-gélido", "Aumenta a força em 40%", if(E4="Raio elétrico", "Aumenta a força em 50%", if(E4="Emboscada", "Aumenta a força 25% das vezes", if(E4="Defesa", "Aumenta a defesa do equipamento em 10%", if(E4="Passo das Sombras", "Evita ferimentos 15% das vezes", if(E4="Detectar segredo", "Aumenta o número máximo de artefatos e itens de raid encontrados por cada membro do grupo em +1", if(E4="Encontrar mágica", "Aumenta o número máximo de artefatos e itens de raid encontrados por cada membro do grupo em +2", if(E4="Aura de proteção", "Aumenta a taxa de sobrevivência do grupo em 8%", if(E4="Revide", "Aumenta a força do equipamento em 20%", if(E4="Mestre das armas", "Aumenta a força do equipamento em 75%", if(E4="Arquimago 1", "Aumenta a força dos feiticeiros do grupo em 10%", if(E4="Arquimago 2", "Aumenta a força dos feiticeiros do grupo em 20%", if(E4="Arquimago 3", "Aumenta a força dos feiticeiros do grupo em 30%", if(E4="Energético 1", "Reduz o tempo de espera depois da missão em 50%", if(E4="Energético 2", "Reduz o tempo de espera depois da missão em 75%", if(E4="Energético 3", "Reduz o tempo de espera depois da missão em 100%", if(E4="Cuidadoso 1", "Diminui a chance de quebra de equipamento em 15% das vezes", if(E4="Cuidadoso 2", "Diminui a chance de quebra de equipamento em 30% das vezes", if(E4="Cuidadoso 3", "Diminui a chance de quebra de equipamento em 50% das vezes", if(E4="Ganancioso 1", "Encontra mais 50% de ouro durante as missões", if(E4="Ganancioso 2", "Encontra mais 100% de ouro durante as missões", if(E4="Ganancioso 3", "Encontra mais 200% de ouro durante as missões", if(E4="Curandeiro 1", "Reduz o tempo de cura de companheiros em 10%", if(E4="Curandeiro 2", "Reduz o tempo de cura de companheiros em 25%", if(E4="Curandeiro 3", "Reduz o tempo de cura de companheiros em 50%", if(E4="Sortudo 1", "Evita ferimentos 10% das vezes", if(E4="Sortudo 2", "Evita ferimentos 20% das vezes", if(E4="Sortudo 3", "Evita ferimentos 30% das vezes", if(E4="Protetor 1", "Aumenta a taxa de sobrevivência do grupo em 2%", if(E4="Protetor 2", "Aumenta a taxa de sobrevivência do grupo em 5%", if(E4="Protetor 3", "Aumenta a taxa de sobrevivência do grupo em 10%", if(E4="Resistente 1", "Obtém pelo menos 25% de experiência quando ferido e a missão é bem sucedida", if(E4="Resistente 2", "Obtém pelo menos 50% de experiência quando ferido e a missão é bem sucedida", if(E4="Resistente 3", "Obtém pelo menos 100% de experiência quando ferido e a missão é bem sucedida", if(E4="Engenhoso 1", "Impede que 1 peça de equipamento se quebre durante a missão", if(E4="Engenhoso 2", "Impede que 2 peças de equipamento se quebre durante a missão", if(E4="Engenhoso 3", "Impede que 3 peças de equipamento se quebre durante a missão", if(E4="Reviver 1", "Revive um companheiro derrotado 5% das vezes", if(E4="Reviver 2", "Revive um companheiro derrotado 10% das vezes", if(E4="Reviver 3", "Revive um companheiro derrotado 15% das vezes", if(E4="Catador 1", "Aumenta o número mínimo de itens e artefatos encontrados em +1", if(E4="Catador 2", "Aumenta o número mínimo de itens e artefatos encontrados em +2", if(E4="Catador 3", "Aumenta o número mínimo de itens e artefatos encontrados em +3", if(E4="Fornecedor 1", "Reduz a chance de companheiros quebrarem o equipamento em 5%", if(E4="Fornecedor 2", "Reduz a chance de companheiros quebrarem o equipamento em 10%", if(E4="Fornecedor 3", "Reduz a chance de companheiros quebrarem o equipamento em 15%", if(E4="Suporte 1", "Impede que o equipamento de um companheiro se quebre 1 vez", if(E4="Suporte 2", "Impede que o equipamento de um companheiro se quebre 2 vezes", if(E4="Suporte 3", "Impede que o equipamento de um companheiro se quebre 3 vezes", if(E4="Caça-tesouros 1", "Aumenta o número máximo de artefatos e itens de raid encontrados em +2", if(E4="Caça-tesouros 2", "Aumenta o número máximo de artefatos e itens de raid encontrados em +4", if(E4="Caça-tesouros 3", "Aumenta o número máximo de artefatos e itens de raid encontrados em +6", if(E4="Sábio 1", "25% de bônus de experiência", if(E4="Sábio 2", "50% de bônus de experiência", if(E4="Sábio 3", "100% de bônus de experiência", if(E4="Amazona 1", "Aumenta a taxa de sobrevivência de membros femininos do grupo em 5%", if(E4="Amazona 2", "Aumenta a taxa de sobrevivência de membros femininos do grupo em 10%", if(E4="Amazona 3", "Aumenta a taxa de sobrevivência de membros femininos do grupo em 25%", if(E4="Companheiro de Guerra 1", "Aumenta a taxa de sobrevivência de membros masculinos do grupo em 5%", if(E4="Companheiro de Guerra 2", "Aumenta a taxa de sobrevivência de membros masculinos do grupo em 10%", if(E4="Companheiro de Guerra 3", "Aumenta a taxa de sobrevivência de membros masculinos do grupo em 25%", if(E4="Comandante 1", "Aumenta a força dos guerreiros do grupo em 15%", if(E4="Comandante 2", "Aumenta a força dos guerreiros do grupo em 25%", if(E4="Comandante 3", "Aumenta a força dos guerreiros do grupo em 50%", if(E4="Gangster 1", "Aumenta a força do equipamento em 10%", if(or(E4="Gangster 2", E4="Armadura do Mago"), "Aumenta a força do equipamento em 25%", if(E4="Gangster 3", "Aumenta a força do equipamento em 50%", if(E4="Líder 1", "Aumenta o número de companheiros em +1", if(E4="Líder 2", "Aumenta o número de companheiros em +2", if(E4="Líder 3", "Aumenta o número de companheiros em +3", if(E4="Velocista 1", "Reduz a duração da missão em 10%", if(E4="Velocista 2", "Reduz a duração da missão em 25%", if(E4="Velocista 3", "Reduz a duração da missão em 50%", )))))))))))))))))))))))))))))))))))))))))))))))))))))))))))))))))))))))))))) -> Encontra mais 50% de ouro durante as missões | H4: TRUE | I4: Baú de Couro
B5: Anel ferradura | C5: Anel | D5: 20 | E5: Líder 1 | F5: Impecável | G5: =IF(or(E5="Bola de fogo", E5="Cortar", E5="Esmagar"), "Aumenta a força em 25%", if(E5="Pele de pedra", "Aumenta a força em 30%", if(E5="Berserker", "Aumenta a força em 35%", if(E5="Cone-gélido", "Aumenta a força em 40%", if(E5="Raio elétrico", "Aumenta a força em 50%", if(E5="Emboscada", "Aumenta a força 25% das vezes", if(E5="Defesa", "Aumenta a defesa do equipamento em 10%", if(E5="Passo das Sombras", "Evita ferimentos 15% das vezes", if(E5="Detectar segredo", "Aumenta o número máximo de artefatos e itens de raid encontrados por cada membro do grupo em +1", if(E5="Encontrar mágica", "Aumenta o número máximo de artefatos e itens de raid encontrados por cada membro do grupo em +2", if(E5="Aura de proteção", "Aumenta a taxa de sobrevivência do grupo em 8%", if(E5="Revide", "Aumenta a força do equipamento em 20%", if(E5="Mestre das armas", "Aumenta a força do equipamento em 75%", if(E5="Arquimago 1", "Aumenta a força dos feiticeiros do grupo em 10%", if(E5="Arquimago 2", "Aumenta a força dos feiticeiros do grupo em 20%", if(E5="Arquimago 3", "Aumenta a força dos feiticeiros do grupo em 30%", if(E5="Energético 1", "Reduz o tempo de espera depois da missão em 50%", if(E5="Energético 2", "Reduz o tempo de espera depois da missão em 75%", if(E5="Energético 3", "Reduz o tempo de espera depois da missão em 100%", if(E5="Cuidadoso 1", "Diminui a chance de quebra de equipamento em 15% das vezes", if(E5="Cuidadoso 2", "Diminui a chance de quebra de equipamento em 30% das vezes", if(E5="Cuidadoso 3", "Diminui a chance de quebra de equipamento em 50% das vezes", if(E5="Ganancioso 1", "Encontra mais 50% de ouro durante as missões", if(E5="Ganancioso 2", "Encontra mais 100% de ouro durante as missões", if(E5="Ganancioso 3", "Encontra mais 200% de ouro durante as missões", if(E5="Curandeiro 1", "Reduz o tempo de cura de companheiros em 10%", if(E5="Curandeiro 2", "Reduz o tempo de cura de companheiros em 25%", if(E5="Curandeiro 3", "Reduz o tempo de cura de companheiros em 50%", if(E5="Sortudo 1", "Evita ferimentos 10% das vezes", if(E5="Sortudo 2", "Evita ferimentos 20% das vezes", if(E5="Sortudo 3", "Evita ferimentos 30% das vezes", if(E5="Protetor 1", "Aumenta a taxa de sobrevivência do grupo em 2%", if(E5="Protetor 2", "Aumenta a taxa de sobrevivência do grupo em 5%", if(E5="Protetor 3", "Aumenta a taxa de sobrevivência do grupo em 10%", if(E5="Resistente 1", "Obtém pelo menos 25% de experiência quando ferido e a missão é bem sucedida", if(E5="Resistente 2", "Obtém pelo menos 50% de experiência quando ferido e a missão é bem sucedida", if(E5="Resistente 3", "Obtém pelo menos 100% de experiência quando ferido e a missão é bem sucedida", if(E5="Engenhoso 1", "Impede que 1 peça de equipamento se quebre durante a missão", if(E5="Engenhoso 2", "Impede que 2 peças de equipamento se quebre durante a missão", if(E5="Engenhoso 3", "Impede que 3 peças de equipamento se quebre durante a missão", if(E5="Reviver 1", "Revive um companheiro derrotado 5% das vezes", if(E5="Reviver 2", "Revive um companheiro derrotado 10% das vezes", if(E5="Reviver 3", "Revive um companheiro derrotado 15% das vezes", if(E5="Catador 1", "Aumenta o número mínimo de itens e artefatos encontrados em +1", if(E5="Catador 2", "Aumenta o número mínimo de itens e artefatos encontrados em +2", if(E5="Catador 3", "Aumenta o número mínimo de itens e artefatos encontrados em +3", if(E5="Fornecedor 1", "Reduz a chance de companheiros quebrarem o equipamento em 5%", if(E5="Fornecedor 2", "Reduz a chance de companheiros quebrarem o equipamento em 10%", if(E5="Fornecedor 3", "Reduz a chance de companheiros quebrarem o equipamento em 15%", if(E5="Suporte 1", "Impede que o equipamento de um companheiro se quebre 1 vez", if(E5="Suporte 2", "Impede que o equipamento de um companheiro se quebre 2 vezes", if(E5="Suporte 3", "Impede que o equipamento de um companheiro se quebre 3 vezes", if(E5="Caça-tesouros 1", "Aumenta o número máximo de artefatos e itens de raid encontrados em +2", if(E5="Caça-tesouros 2", "Aumenta o número máximo de artefatos e itens de raid encontrados em +4", if(E5="Caça-tesouros 3", "Aumenta o número máximo de artefatos e itens de raid encontrados em +6", if(E5="Sábio 1", "25% de bônus de experiência", if(E5="Sábio 2", "50% de bônus de experiência", if(E5="Sábio 3", "100% de bônus de experiência", if(E5="Amazona 1", "Aumenta a taxa de sobrevivência de membros femininos do grupo em 5%", if(E5="Amazona 2", "Aumenta a taxa de sobrevivência de membros femininos do grupo em 10%", if(E5="Amazona 3", "Aumenta a taxa de sobrevivência de membros femininos do grupo em 25%", if(E5="Companheiro de Guerra 1", "Aumenta a taxa de sobrevivência de membros masculinos do grupo em 5%", if(E5="Companheiro de Guerra 2", "Aumenta a taxa de sobrevivência de membros masculinos do grupo em 10%", if(E5="Companheiro de Guerra 3", "Aumenta a taxa de sobrevivência de membros masculinos do grupo em 25%", if(E5="Comandante 1", "Aumenta a força dos guerreiros do grupo em 15%", if(E5="Comandante 2", "Aumenta a força dos guerreiros do grupo em 25%", if(E5="Comandante 3", "Aumenta a força dos guerreiros do grupo em 50%", if(E5="Gangster 1", "Aumenta a força do equipamento em 10%", if(or(E5="Gangster 2", E5="Armadura do Mago"), "Aumenta a força do equipamento em 25%", if(E5="Gangster 3", "Aumenta a força do equipamento em 50%", if(E5="Líder 1", "Aumenta o número de companheiros em +1", if(E5="Líder 2", "Aumenta o número de companheiros em +2", if(E5="Líder 3", "Aumenta o número de companheiros em +3", if(E5="Velocista 1", "Reduz a duração da missão em 10%", if(E5="Velocista 2", "Reduz a duração da missão em 25%", if(E5="Velocista 3", "Reduz a duração da missão em 50%", )))))))))))))))))))))))))))))))))))))))))))))))))))))))))))))))))))))))))))) -> Aumenta o número de companheiros em +1 | H5: TRUE | I5: Luck of the Irish Pack
B6: Perseguindo a lua | C6: Anel | D6: 22 | E6: Caça-tesouros 1 | F6: Impecável | G6: =IF(or(E6="Bola de fogo", E6="Cortar", E6="Esmagar"), "Aumenta a força em 25%", if(E6="Pele de pedra", "Aumenta a força em 30%", if(E6="Berserker", "Aumenta a força em 35%", if(E6="Cone-gélido", "Aumenta a força em 40%", if(E6="Raio elétrico", "Aumenta a força em 50%", if(E6="Emboscada", "Aumenta a força 25% das vezes", if(E6="Defesa", "Aumenta a defesa do equipamento em 10%", if(E6="Passo das Sombras", "Evita ferimentos 15% das vezes", if(E6="Detectar segredo", "Aumenta o número máximo de artefatos e itens de raid encontrados por cada membro do grupo em +1", if(E6="Encontrar mágica", "Aumenta o número máximo de artefatos e itens de raid encontrados por cada membro do grupo em +2", if(E6="Aura de proteção", "Aumenta a taxa de sobrevivência do grupo em 8%", if(E6="Revide", "Aumenta a força do equipamento em 20%", if(E6="Mestre das armas", "Aumenta a força do equipamento em 75%", if(E6="Arquimago 1", "Aumenta a força dos feiticeiros do grupo em 10%", if(E6="Arquimago 2", "Aumenta a força dos feiticeiros do grupo em 20%", if(E6="Arquimago 3", "Aumenta a força dos feiticeiros do grupo em 30%", if(E6="Energético 1", "Reduz o tempo de espera depois da missão em 50%", if(E6="Energético 2", "Reduz o tempo de espera depois da missão em 75%", if(E6="Energético 3", "Reduz o tempo de espera depois da missão em 100%", if(E6="Cuidadoso 1", "Diminui a chance de quebra de equipamento em 15% das vezes", if(E6="Cuidadoso 2", "Diminui a chance de quebra de equipamento em 30% das vezes", if(E6="Cuidadoso 3", "Diminui a chance de quebra de equipamento em 50% das vezes", if(E6="Ganancioso 1", "Encontra mais 50% de ouro durante as missões", if(E6="Ganancioso 2", "Encontra mais 100% de ouro durante as missões", if(E6="Ganancioso 3", "Encontra mais 200% de ouro durante as missões", if(E6="Curandeiro 1", "Reduz o tempo de cura de companheiros em 10%", if(E6="Curandeiro 2", "Reduz o tempo de cura de companheiros em 25%", if(E6="Curandeiro 3", "Reduz o tempo de cura de companheiros em 50%", if(E6="Sortudo 1", "Evita ferimentos 10% das vezes", if(E6="Sortudo 2", "Evita ferimentos 20% das vezes", if(E6="Sortudo 3", "Evita ferimentos 30% das vezes", if(E6="Protetor 1", "Aumenta a taxa de sobrevivência do grupo em 2%", if(E6="Protetor 2", "Aumenta a taxa de sobrevivência do grupo em 5%", if(E6="Protetor 3", "Aumenta a taxa de sobrevivência do grupo em 10%", if(E6="Resistente 1", "Obtém pelo menos 25% de experiência quando ferido e a missão é bem sucedida", if(E6="Resistente 2", "Obtém pelo menos 50% de experiência quando ferido e a missão é bem sucedida", if(E6="Resistente 3", "Obtém pelo menos 100% de experiência quando ferido e a missão é bem sucedida", if(E6="Engenhoso 1", "Impede que 1 peça de equipamento se quebre durante a missão", if(E6="Engenhoso 2", "Impede que 2 peças de equipamento se quebre durante a missão", if(E6="Engenhoso 3", "Impede que 3 peças de equipamento se quebre durante a missão", if(E6="Reviver 1", "Revive um companheiro derrotado 5% das vezes", if(E6="Reviver 2", "Revive um companheiro derrotado 10% das vezes", if(E6="Reviver 3", "Revive um companheiro derrotado 15% das vezes", if(E6="Catador 1", "Aumenta o número mínimo de itens e artefatos encontrados em +1", if(E6="Catador 2", "Aumenta o número mínimo de itens e artefatos encontrados em +2", if(E6="Catador 3", "Aumenta o número mínimo de itens e artefatos encontrados em +3", if(E6="Fornecedor 1", "Reduz a chance de companheiros quebrarem o equipamento em 5%", if(E6="Fornecedor 2", "Reduz a chance de companheiros quebrarem o equipamento em 10%", if(E6="Fornecedor 3", "Reduz a chance de companheiros quebrarem o equipamento em 15%", if(E6="Suporte 1", "Impede que o equipamento de um companheiro se quebre 1 vez", if(E6="Suporte 2", "Impede que o equipamento de um companheiro se quebre 2 vezes", if(E6="Suporte 3", "Impede que o equipamento de um companheiro se quebre 3 vezes", if(E6="Caça-tesouros 1", "Aumenta o número máximo de artefatos e itens de raid encontrados em +2", if(E6="Caça-tesouros 2", "Aumenta o número máximo de artefatos e itens de raid encontrados em +4", if(E6="Caça-tesouros 3", "Aumenta o número máximo de artefatos e itens de raid encontrados em +6", if(E6="Sábio 1", "25% de bônus de experiência", if(E6="Sábio 2", "50% de bônus de experiência", if(E6="Sábio 3", "100% de bônus de experiência", if(E6="Amazona 1", "Aumenta a taxa de sobrevivência de membros femininos do grupo em 5%", if(E6="Amazona 2", "Aumenta a taxa de sobrevivência de membros femininos do grupo em 10%", if(E6="Amazona 3", "Aumenta a taxa de sobrevivência de membros femininos do grupo em 25%", if(E6="Companheiro de Guerra 1", "Aumenta a taxa de sobrevivência de membros masculinos do grupo em 5%", if(E6="Companheiro de Guerra 2", "Aumenta a taxa de sobrevivência de membros masculinos do grupo em 10%", if(E6="Companheiro de Guerra 3", "Aumenta a taxa de sobrevivência de membros masculinos do grupo em 25%", if(E6="Comandante 1", "Aumenta a força dos guerreiros do grupo em 15%", if(E6="Comandante 2", "Aumenta a força dos guerreiros do grupo em 25%", if(E6="Comandante 3", "Aumenta a força dos guerreiros do grupo em 50%", if(E6="Gangster 1", "Aumenta a força do equipamento em 10%", if(or(E6="Gangster 2", E6="Armadura do Mago"), "Aumenta a força do equipamento em 25%", if(E6="Gangster 3", "Aumenta a força do equipamento em 50%", if(E6="Líder 1", "Aumenta o número de companheiros em +1", if(E6="Líder 2", "Aumenta o número de companheiros em +2", if(E6="Líder 3", "Aumenta o número de companheiros em +3", if(E6="Velocista 1", "Reduz a duração da missão em 10%", if(E6="Velocista 2", "Reduz a duração da missão em 25%", if(E6="Velocista 3", "Reduz a duração da missão em 50%", )))))))))))))))))))))))))))))))))))))))))))))))))))))))))))))))))))))))))))) -> Aumenta o número máximo de artefatos e itens de raid encontrados em +2 | H6: TRUE | I6: Lunar Equinox Pack
